Workbook

Sheet Read Me
A1: XP ↔ AE rebalance model (Enterprise)
A3: What this is
A4: Revised Enterprise assignments built to cut the number of AEs each XP works with, while holding the account cap, leadership holds, capacity and time-zone fit. Segmentation: every State and every Local ENT account is Enterprise (no special-entity overrides), plus DC. Source: Account Team export 9/21/26 (277 records, 209 countable, former customers excluded); AE mapping from the State map (6/12/26) and Local ENT map (6/30/26).
A6: What to fill in
A7: Column P on the Assignments tab (yellow). Enter Y where an account is Service Cloud Advanced; that marks it complex regardless of capability count. Example: an account with 5 capabilities and Y in column P counts as complex.
A8: Capabilities (column O) are counted from Account Product Categories, excluding Service Cloud, Engagement Cloud, Operations Cloud and anything named Credits. Websites, Portals, & Intranets counts as one. The counted list is in column U.
A9: You can also change any Revised XP (column G). Manager, time-zone fit, cap, AE count and every check recalculate.
A11: Rules applied
A12: Cap: no more than 17 countable accounts per Enterprise XP. Allocated child records do not count and travel with their parent.
A13: Holds: San Antonio with Steffany Amador; District of Columbia with Paige Wendle; Denver with a Savannah Lane report; Columbus with an Ashley Hill report. Preferences (9/21): Steffany takes Texas; Colleen keeps Los Angeles and GLACVCD rather than California state agencies.
A14: Carolina Prieto keeps her current Enterprise book except Connecticut and Maine, which go to Halena Martin. Her book is excluded from the 17-account cap and time-zone rule. Paige Wendle keeps Washington. The open XP2 headcount is Pacific time.
A15: Capacity: no more than one third of an XP's countable book may be complex (more than 7 capabilities, or Service Cloud Advanced).
... A44: Method, sources and full caveats: research/ENT-book-growth-tiering-hypothesis.md

Sheet XP Check
A1: XP | B1: Manager | C1: Level | D1: XP Time Zone | E1: Countable Accounts | F1: Cap | G1: Cap Status | H1: ARR | I1: AEs Worked With (Revised) | J1: AEs Worked With (WIP) | K1: Accounts Outside ±1 hr | L1: Complex Accounts | M1: Max Complex (1/3) | N1: Capacity Status | O1: Accounts Missing Capability Data | Q1: Account cap | R1: 17 | T1: Tier 1 Growth | U1: Tier 2 Expansion | V1: Tier 3 Defend | W1: Tier 4 Maintain | X1: Growth Share | Y1: Growth Load | Z1: Defend ARR
A2: =Lookups!A2 | B2: =Lookups!B2 | C2: =Lookups!C2 | D2: =Lookups!E2 | E2: =COUNTIFS(Assignments!$G$2:$G$278,A2,Assignments!$N$2:$N$278,"Yes") | F2: =$R$1 | G2: =IF(E2<=F2,"OK","OVER BY "&(E2-F2)) | H2: =SUMIFS(Assignments!$M$2:$M$278,Assignments!$G$2:$G$278,A2) | I2: =SUMPRODUCT((Assignments!$G$2:$G$278=A2)/COUNTIFS(Assignments!$G$2:$G$278,Assignments!$G$2:$G$278,Assignments!$E$2:$E$278,Assignments!$E$2:$E$278)) | J2: =SUMPRODUCT((Assignments!$F$2:$F$278=A2)/COUNTIFS(Assignments!$F$2:$F$278,Assignments!$F$2:$F$278,Assignments!$E$2:$E$278,Assignments!$E$2:$E$278)) | K2: =COUNTIFS(Assignments!$G$2:$G$278,A2,Assignments!$N$2:$N$278,"Yes",Assignments!$L$2:$L$278,"No") | L2: =COUNTIFS(Assignments!$G$2:$G$278,A2,Assignments!$Q$2:$Q$278,"Yes") | M2: =ROUNDDOWN(E2*$R$2,0) | N2: =IF(L2>M2,"OVER BY "&(L2-M2),IF(O2>0,"Pending data","OK")) | O2: =COUNTIFS(Assignments!$G$2:$G$278,A2,Assignments!$Q$2:$Q$278,"Pending") | Q2: Complex share limit | R2: 0.33333333 | T2: =COUNTIFS(Assignments!$G$2:$G$278,$A2,Assignments!$N$2:$N$278,"Yes",Assignments!$AB$2:$AB$278,1) | U2: =COUNTIFS(Assignments!$G$2:$G$278,$A2,Assignments!$N$2:$N$278,"Yes",Assignments!$AB$2:$AB$278,2) | V2: =COUNTIFS(Assignments!$G$2:$G$278,$A2,Assignments!$N$2:$N$278,"Yes",Assignments!$AB$2:$AB$278,3) | W2: =COUNTIFS(Assignments!$G$2:$G$278,$A2,Assignments!$N$2:$N$278,"Yes",Assignments!$AB$2:$AB$278,4) | X2: =IFERROR((T2+U2)/COUNTIFS(Assignments!$G$2:$G$278,$A2,Assignments!$N$2:$N$278,"Yes"),"") | Y2: =SUMPRODUCT((Assignments!$G$2:$G$278=$A2)*(Assignments!$N$2:$N$278="Yes")*Assignments!$AD$2:$AD$278) | Z2: =SUMIFS(Assignments!$M$2:$M$278,Assignments!$G$2:$G$278,$A2,Assignments!$N$2:$N$278,"Yes",Assignments!$AB$2:$AB$278,3)
A3: =Lookups!A3 | B3: =Lookups!B3 | C3: =Lookups!C3 | D3: =Lookups!E3 | E3: =COUNTIFS(Assignments!$G$2:$G$278,A3,Assignments!$N$2:$N$278,"Yes") | F3: =$R$1 | G3: =IF(E3<=F3,"OK","OVER BY "&(E3-F3)) | H3: =SUMIFS(Assignments!$M$2:$M$278,Assignments!$G$2:$G$278,A3) | I3: =SUMPRODUCT((Assignments!$G$2:$G$278=A3)/COUNTIFS(Assignments!$G$2:$G$278,Assignments!$G$2:$G$278,Assignments!$E$2:$E$278,Assignments!$E$2:$E$278)) | J3: =SUMPRODUCT((Assignments!$F$2:$F$278=A3)/COUNTIFS(Assignments!$F$2:$F$278,Assignments!$F$2:$F$278,Assignments!$E$2:$E$278,Assignments!$E$2:$E$278)) | K3: =COUNTIFS(Assignments!$G$2:$G$278,A3,Assignments!$N$2:$N$278,"Yes",Assignments!$L$2:$L$278,"No") | L3: =COUNTIFS(Assignments!$G$2:$G$278,A3,Assignments!$Q$2:$Q$278,"Yes") | M3: =ROUNDDOWN(E3*$R$2,0) | N3: =IF(L3>M3,"OVER BY "&(L3-M3),IF(O3>0,"Pending data","OK")) | O3: =COUNTIFS(Assignments!$G$2:$G$278,A3,Assignments!$Q$2:$Q$278,"Pending") | Q3: Complex threshold (capabilities greater than) | R3: =Assignments!$W$1 | T3: =COUNTIFS(Assignments!$G$2:$G$278,$A3,Assignments!$N$2:$N$278,"Yes",Assignments!$AB$2:$AB$278,1) | U3: =COUNTIFS(Assignments!$G$2:$G$278,$A3,Assignments!$N$2:$N$278,"Yes",Assignments!$AB$2:$AB$278,2) | V3: =COUNTIFS(Assignments!$G$2:$G$278,$A3,Assignments!$N$2:$N$278,"Yes",Assignments!$AB$2:$AB$278,3) | W3: =COUNTIFS(Assignments!$G$2:$G$278,$A3,Assignments!$N$2:$N$278,"Yes",Assignments!$AB$2:$AB$278,4) | X3: =IFERROR((T3+U3)/COUNTIFS(Assignments!$G$2:$G$278,$A3,Assignments!$N$2:$N$278,"Yes"),"") | Y3: =SUMPRODUCT((Assignments!$G$2:$G$278=$A3)*(Assignments!$N$2:$N$278="Yes")*Assignments!$AD$2:$AD$278) | Z3: =SUMIFS(Assignments!$M$2:$M$278,Assignments!$G$2:$G$278,$A3,Assignments!$N$2:$N$278,"Yes",Assignments!$AB$2:$AB$278,3)
A4: =Lookups!A4 | B4: =Lookups!B4 | C4: =Lookups!C4 | D4: =Lookups!E4 | E4: =COUNTIFS(Assignments!$G$2:$G$278,A4,Assignments!$N$2:$N$278,"Yes") | F4: =$R$1 | G4: =IF(E4<=F4,"OK","OVER BY "&(E4-F4)) | H4: =SUMIFS(Assignments!$M$2:$M$278,Assignments!$G$2:$G$278,A4) | I4: =SUMPRODUCT((Assignments!$G$2:$G$278=A4)/COUNTIFS(Assignments!$G$2:$G$278,Assignments!$G$2:$G$278,Assignments!$E$2:$E$278,Assignments!$E$2:$E$278)) | J4: =SUMPRODUCT((Assignments!$F$2:$F$278=A4)/COUNTIFS(Assignments!$F$2:$F$278,Assignments!$F$2:$F$278,Assignments!$E$2:$E$278,Assignments!$E$2:$E$278)) | K4: =COUNTIFS(Assignments!$G$2:$G$278,A4,Assignments!$N$2:$N$278,"Yes",Assignments!$L$2:$L$278,"No") | L4: =COUNTIFS(Assignments!$G$2:$G$278,A4,Assignments!$Q$2:$Q$278,"Yes") | M4: =ROUNDDOWN(E4*$R$2,0) | N4: =IF(L4>M4,"OVER BY "&(L4-M4),IF(O4>0,"Pending data","OK")) | O4: =COUNTIFS(Assignments!$G$2:$G$278,A4,Assignments!$Q$2:$Q$278,"Pending") | Q4: Cap, share limit and threshold are user-provided (9/21 instruction). Edit the threshold on Assignments cell W1. | T4: =COUNTIFS(Assignments!$G$2:$G$278,$A4,Assignments!$N$2:$N$278,"Yes",Assignments!$AB$2:$AB$278,1) | U4: =COUNTIFS(Assignments!$G$2:$G$278,$A4,Assignments!$N$2:$N$278,"Yes",Assignments!$AB$2:$AB$278,2) | V4: =COUNTIFS(Assignments!$G$2:$G$278,$A4,Assignments!$N$2:$N$278,"Yes",Assignments!$AB$2:$AB$278,3) | W4: =COUNTIFS(Assignments!$G$2:$G$278,$A4,Assignments!$N$2:$N$278,"Yes",Assignments!$AB$2:$AB$278,4) | X4: =IFERROR((T4+U4)/COUNTIFS(Assignments!$G$2:$G$278,$A4,Assignments!$N$2:$N$278,"Yes"),"") | Y4: =SUMPRODUCT((Assignments!$G$2:$G$278=$A4)*(Assignments!$N$2:$N$278="Yes")*Assignments!$AD$2:$AD$278) | Z4: =SUMIFS(Assignments!$M$2:$M$278,Assignments!$G$2:$G$278,$A4,Assignments!$N$2:$N$278,"Yes",Assignments!$AB$2:$AB$278,3)
A5: =Lookups!A5 | B5: =Lookups!B5 | C5: =Lookups!C5 | D5: =Lookups!E5 | E5: =COUNTIFS(Assignments!$G$2:$G$278,A5,Assignments!$N$2:$N$278,"Yes") | F5: =$R$1 | G5: =IF(E5<=F5,"OK","OVER BY "&(E5-F5)) | H5: =SUMIFS(Assignments!$M$2:$M$278,Assignments!$G$2:$G$278,A5) | I5: =SUMPRODUCT((Assignments!$G$2:$G$278=A5)/COUNTIFS(Assignments!$G$2:$G$278,Assignments!$G$2:$G$278,Assignments!$E$2:$E$278,Assignments!$E$2:$E$278)) | J5: =SUMPRODUCT((Assignments!$F$2:$F$278=A5)/COUNTIFS(Assignments!$F$2:$F$278,Assignments!$F$2:$F$278,Assignments!$E$2:$E$278,Assignments!$E$2:$E$278)) | K5: =COUNTIFS(Assignments!$G$2:$G$278,A5,Assignments!$N$2:$N$278,"Yes",Assignments!$L$2:$L$278,"No") | L5: =COUNTIFS(Assignments!$G$2:$G$278,A5,Assignments!$Q$2:$Q$278,"Yes") | M5: =ROUNDDOWN(E5*$R$2,0) | N5: =IF(L5>M5,"OVER BY "&(L5-M5),IF(O5>0,"Pending data","OK")) | O5: =COUNTIFS(Assignments!$G$2:$G$278,A5,Assignments!$Q$2:$Q$278,"Pending") | T5: =COUNTIFS(Assignments!$G$2:$G$278,$A5,Assignments!$N$2:$N$278,"Yes",Assignments!$AB$2:$AB$278,1) | U5: =COUNTIFS(Assignments!$G$2:$G$278,$A5,Assignments!$N$2:$N$278,"Yes",Assignments!$AB$2:$AB$278,2) | V5: =COUNTIFS(Assignments!$G$2:$G$278,$A5,Assignments!$N$2:$N$278,"Yes",Assignments!$AB$2:$AB$278,3) | W5: =COUNTIFS(Assignments!$G$2:$G$278,$A5,Assignments!$N$2:$N$278,"Yes",Assignments!$AB$2:$AB$278,4) | X5: =IFERROR((T5+U5)/COUNTIFS(Assignments!$G$2:$G$278,$A5,Assignments!$N$2:$N$278,"Yes"),"") | Y5: =SUMPRODUCT((Assignments!$G$2:$G$278=$A5)*(Assignments!$N$2:$N$278="Yes")*Assignments!$AD$2:$AD$278) | Z5: =SUMIFS(Assignments!$M$2:$M$278,Assignments!$G$2:$G$278,$A5,Assignments!$N$2:$N$278,"Yes",Assignments!$AB$2:$AB$278,3)
A6: =Lookups!A6 | B6: =Lookups!B6 | C6: =Lookups!C6 | D6: =Lookups!E6 | E6: =COUNTIFS(Assignments!$G$2:$G$278,A6,Assignments!$N$2:$N$278,"Yes") | F6: =$R$1 | G6: =IF(E6<=F6,"OK","OVER BY "&(E6-F6)) | H6: =SUMIFS(Assignments!$M$2:$M$278,Assignments!$G$2:$G$278,A6) | I6: =SUMPRODUCT((Assignments!$G$2:$G$278=A6)/COUNTIFS(Assignments!$G$2:$G$278,Assignments!$G$2:$G$278,Assignments!$E$2:$E$278,Assignments!$E$2:$E$278)) | J6: =SUMPRODUCT((Assignments!$F$2:$F$278=A6)/COUNTIFS(Assignments!$F$2:$F$278,Assignments!$F$2:$F$278,Assignments!$E$2:$E$278,Assignments!$E$2:$E$278)) | K6: =COUNTIFS(Assignments!$G$2:$G$278,A6,Assignments!$N$2:$N$278,"Yes",Assignments!$L$2:$L$278,"No") | L6: =COUNTIFS(Assignments!$G$2:$G$278,A6,Assignments!$Q$2:$Q$278,"Yes") | M6: =ROUNDDOWN(E6*$R$2,0) | N6: =IF(L6>M6,"OVER BY "&(L6-M6),IF(O6>0,"Pending data","OK")) | O6: =COUNTIFS(Assignments!$G$2:$G$278,A6,Assignments!$Q$2:$Q$278,"Pending") | T6: =COUNTIFS(Assignments!$G$2:$G$278,$A6,Assignments!$N$2:$N$278,"Yes",Assignments!$AB$2:$AB$278,1) | U6: =COUNTIFS(Assignments!$G$2:$G$278,$A6,Assignments!$N$2:$N$278,"Yes",Assignments!$AB$2:$AB$278,2) | V6: =COUNTIFS(Assignments!$G$2:$G$278,$A6,Assignments!$N$2:$N$278,"Yes",Assignments!$AB$2:$AB$278,3) | W6: =COUNTIFS(Assignments!$G$2:$G$278,$A6,Assignments!$N$2:$N$278,"Yes",Assignments!$AB$2:$AB$278,4) | X6: =IFERROR((T6+U6)/COUNTIFS(Assignments!$G$2:$G$278,$A6,Assignments!$N$2:$N$278,"Yes"),"") | Y6: =SUMPRODUCT((Assignments!$G$2:$G$278=$A6)*(Assignments!$N$2:$N$278="Yes")*Assignments!$AD$2:$AD$278) | Z6: =SUMIFS(Assignments!$M$2:$M$278,Assignments!$G$2:$G$278,$A6,Assignments!$N$2:$N$278,"Yes",Assignments!$AB$2:$AB$278,3)
A7: =Lookups!A7 | B7: =Lookups!B7 | C7: =Lookups!C7 | D7: =Lookups!E7 | E7: =COUNTIFS(Assignments!$G$2:$G$278,A7,Assignments!$N$2:$N$278,"Yes") | F7: =$R$1 | G7: =IF(E7<=F7,"OK","OVER BY "&(E7-F7)) | H7: =SUMIFS(Assignments!$M$2:$M$278,Assignments!$G$2:$G$278,A7) | I7: =SUMPRODUCT((Assignments!$G$2:$G$278=A7)/COUNTIFS(Assignments!$G$2:$G$278,Assignments!$G$2:$G$278,Assignments!$E$2:$E$278,Assignments!$E$2:$E$278)) | J7: =SUMPRODUCT((Assignments!$F$2:$F$278=A7)/COUNTIFS(Assignments!$F$2:$F$278,Assignments!$F$2:$F$278,Assignments!$E$2:$E$278,Assignments!$E$2:$E$278)) | K7: =COUNTIFS(Assignments!$G$2:$G$278,A7,Assignments!$N$2:$N$278,"Yes",Assignments!$L$2:$L$278,"No") | L7: =COUNTIFS(Assignments!$G$2:$G$278,A7,Assignments!$Q$2:$Q$278,"Yes") | M7: =ROUNDDOWN(E7*$R$2,0) | N7: =IF(L7>M7,"OVER BY "&(L7-M7),IF(O7>0,"Pending data","OK")) | O7: =COUNTIFS(Assignments!$G$2:$G$278,A7,Assignments!$Q$2:$Q$278,"Pending") | T7: =COUNTIFS(Assignments!$G$2:$G$278,$A7,Assignments!$N$2:$N$278,"Yes",Assignments!$AB$2:$AB$278,1) | U7: =COUNTIFS(Assignments!$G$2:$G$278,$A7,Assignments!$N$2:$N$278,"Yes",Assignments!$AB$2:$AB$278,2) | V7: =COUNTIFS(Assignments!$G$2:$G$278,$A7,Assignments!$N$2:$N$278,"Yes",Assignments!$AB$2:$AB$278,3) | W7: =COUNTIFS(Assignments!$G$2:$G$278,$A7,Assignments!$N$2:$N$278,"Yes",Assignments!$AB$2:$AB$278,4) | X7: =IFERROR((T7+U7)/COUNTIFS(Assignments!$G$2:$G$278,$A7,Assignments!$N$2:$N$278,"Yes"),"") | Y7: =SUMPRODUCT((Assignments!$G$2:$G$278=$A7)*(Assignments!$N$2:$N$278="Yes")*Assignments!$AD$2:$AD$278) | Z7: =SUMIFS(Assignments!$M$2:$M$278,Assignments!$G$2:$G$278,$A7,Assignments!$N$2:$N$278,"Yes",Assignments!$AB$2:$AB$278,3)
A8: =Lookups!A8 | B8: =Lookups!B8 | C8: =Lookups!C8 | D8: =Lookups!E8 | E8: =COUNTIFS(Assignments!$G$2:$G$278,A8,Assignments!$N$2:$N$278,"Yes") | F8: =$R$1 | G8: =IF(E8<=F8,"OK","OVER BY "&(E8-F8)) | H8: =SUMIFS(Assignments!$M$2:$M$278,Assignments!$G$2:$G$278,A8) | I8: =SUMPRODUCT((Assignments!$G$2:$G$278=A8)/COUNTIFS(Assignments!$G$2:$G$278,Assignments!$G$2:$G$278,Assignments!$E$2:$E$278,Assignments!$E$2:$E$278)) | J8: =SUMPRODUCT((Assignments!$F$2:$F$278=A8)/COUNTIFS(Assignments!$F$2:$F$278,Assignments!$F$2:$F$278,Assignments!$E$2:$E$278,Assignments!$E$2:$E$278)) | K8: =COUNTIFS(Assignments!$G$2:$G$278,A8,Assignments!$N$2:$N$278,"Yes",Assignments!$L$2:$L$278,"No") | L8: =COUNTIFS(Assignments!$G$2:$G$278,A8,Assignments!$Q$2:$Q$278,"Yes") | M8: =ROUNDDOWN(E8*$R$2,0) | N8: =IF(L8>M8,"OVER BY "&(L8-M8),IF(O8>0,"Pending data","OK")) | O8: =COUNTIFS(Assignments!$G$2:$G$278,A8,Assignments!$Q$2:$Q$278,"Pending") | T8: =COUNTIFS(Assignments!$G$2:$G$278,$A8,Assignments!$N$2:$N$278,"Yes",Assignments!$AB$2:$AB$278,1) | U8: =COUNTIFS(Assignments!$G$2:$G$278,$A8,Assignments!$N$2:$N$278,"Yes",Assignments!$AB$2:$AB$278,2) | V8: =COUNTIFS(Assignments!$G$2:$G$278,$A8,Assignments!$N$2:$N$278,"Yes",Assignments!$AB$2:$AB$278,3) | W8: =COUNTIFS(Assignments!$G$2:$G$278,$A8,Assignments!$N$2:$N$278,"Yes",Assignments!$AB$2:$AB$278,4) | X8: =IFERROR((T8+U8)/COUNTIFS(Assignments!$G$2:$G$278,$A8,Assignments!$N$2:$N$278,"Yes"),"") | Y8: =SUMPRODUCT((Assignments!$G$2:$G$278=$A8)*(Assignments!$N$2:$N$278="Yes")*Assignments!$AD$2:$AD$278) | Z8: =SUMIFS(Assignments!$M$2:$M$278,Assignments!$G$2:$G$278,$A8,Assignments!$N$2:$N$278,"Yes",Assignments!$AB$2:$AB$278,3)
A9: =Lookups!A9 | B9: =Lookups!B9 | C9: =Lookups!C9 | D9: =Lookups!E9 | E9: =COUNTIFS(Assignments!$G$2:$G$278,A9,Assignments!$N$2:$N$278,"Yes") | F9: =$R$1 | G9: =IF(E9<=F9,"OK","OVER BY "&(E9-F9)) | H9: =SUMIFS(Assignments!$M$2:$M$278,Assignments!$G$2:$G$278,A9) | I9: =SUMPRODUCT((Assignments!$G$2:$G$278=A9)/COUNTIFS(Assignments!$G$2:$G$278,Assignments!$G$2:$G$278,Assignments!$E$2:$E$278,Assignments!$E$2:$E$278)) | J9: =SUMPRODUCT((Assignments!$F$2:$F$278=A9)/COUNTIFS(Assignments!$F$2:$F$278,Assignments!$F$2:$F$278,Assignments!$E$2:$E$278,Assignments!$E$2:$E$278)) | K9: =COUNTIFS(Assignments!$G$2:$G$278,A9,Assignments!$N$2:$N$278,"Yes",Assignments!$L$2:$L$278,"No") | L9: =COUNTIFS(Assignments!$G$2:$G$278,A9,Assignments!$Q$2:$Q$278,"Yes") | M9: =ROUNDDOWN(E9*$R$2,0) | N9: =IF(L9>M9,"OVER BY "&(L9-M9),IF(O9>0,"Pending data","OK")) | O9: =COUNTIFS(Assignments!$G$2:$G$278,A9,Assignments!$Q$2:$Q$278,"Pending") | T9: =COUNTIFS(Assignments!$G$2:$G$278,$A9,Assignments!$N$2:$N$278,"Yes",Assignments!$AB$2:$AB$278,1) | U9: =COUNTIFS(Assignments!$G$2:$G$278,$A9,Assignments!$N$2:$N$278,"Yes",Assignments!$AB$2:$AB$278,2) | V9: =COUNTIFS(Assignments!$G$2:$G$278,$A9,Assignments!$N$2:$N$278,"Yes",Assignments!$AB$2:$AB$278,3) | W9: =COUNTIFS(Assignments!$G$2:$G$278,$A9,Assignments!$N$2:$N$278,"Yes",Assignments!$AB$2:$AB$278,4) | X9: =IFERROR((T9+U9)/COUNTIFS(Assignments!$G$2:$G$278,$A9,Assignments!$N$2:$N$278,"Yes"),"") | Y9: =SUMPRODUCT((Assignments!$G$2:$G$278=$A9)*(Assignments!$N$2:$N$278="Yes")*Assignments!$AD$2:$AD$278) | Z9: =SUMIFS(Assignments!$M$2:$M$278,Assignments!$G$2:$G$278,$A9,Assignments!$N$2:$N$278,"Yes",Assignments!$AB$2:$AB$278,3)
A10: =Lookups!A10 | B10: =Lookups!B10 | C10: =Lookups!C10 | D10: =Lookups!E10 | E10: =COUNTIFS(Assignments!$G$2:$G$278,A10,Assignments!$N$2:$N$278,"Yes") | F10: =$R$1 | G10: =IF(E10<=F10,"OK","OVER BY "&(E10-F10)) | H10: =SUMIFS(Assignments!$M$2:$M$278,Assignments!$G$2:$G$278,A10) | I10: =SUMPRODUCT((Assignments!$G$2:$G$278=A10)/COUNTIFS(Assignments!$G$2:$G$278,Assignments!$G$2:$G$278,Assignments!$E$2:$E$278,Assignments!$E$2:$E$278)) | J10: =SUMPRODUCT((Assignments!$F$2:$F$278=A10)/COUNTIFS(Assignments!$F$2:$F$278,Assignments!$F$2:$F$278,Assignments!$E$2:$E$278,Assignments!$E$2:$E$278)) | K10: =COUNTIFS(Assignments!$G$2:$G$278,A10,Assignments!$N$2:$N$278,"Yes",Assignments!$L$2:$L$278,"No") | L10: =COUNTIFS(Assignments!$G$2:$G$278,A10,Assignments!$Q$2:$Q$278,"Yes") | M10: =ROUNDDOWN(E10*$R$2,0) | N10: =IF(L10>M10,"OVER BY "&(L10-M10),IF(O10>0,"Pending data","OK")) | O10: =COUNTIFS(Assignments!$G$2:$G$278,A10,Assignments!$Q$2:$Q$278,"Pending") | T10: =COUNTIFS(Assignments!$G$2:$G$278,$A10,Assignments!$N$2:$N$278,"Yes",Assignments!$AB$2:$AB$278,1) | U10: =COUNTIFS(Assignments!$G$2:$G$278,$A10,Assignments!$N$2:$N$278,"Yes",Assignments!$AB$2:$AB$278,2) | V10: =COUNTIFS(Assignments!$G$2:$G$278,$A10,Assignments!$N$2:$N$278,"Yes",Assignments!$AB$2:$AB$278,3) | W10: =COUNTIFS(Assignments!$G$2:$G$278,$A10,Assignments!$N$2:$N$278,"Yes",Assignments!$AB$2:$AB$278,4) | X10: =IFERROR((T10+U10)/COUNTIFS(Assignments!$G$2:$G$278,$A10,Assignments!$N$2:$N$278,"Yes"),"") | Y10: =SUMPRODUCT((Assignments!$G$2:$G$278=$A10)*(Assignments!$N$2:$N$278="Yes")*Assignments!$AD$2:$AD$278) | Z10: =SUMIFS(Assignments!$M$2:$M$278,Assignments!$G$2:$G$278,$A10,Assignments!$N$2:$N$278,"Yes",Assignments!$AB$2:$AB$278,3)
A11: =Lookups!A11 | B11: =Lookups!B11 | C11: =Lookups!C11 | D11: =Lookups!E11 | E11: =COUNTIFS(Assignments!$G$2:$G$278,A11,Assignments!$N$2:$N$278,"Yes") | F11: =$R$1 | G11: =IF(E11<=F11,"OK","OVER BY "&(E11-F11)) | H11: =SUMIFS(Assignments!$M$2:$M$278,Assignments!$G$2:$G$278,A11) | I11: =SUMPRODUCT((Assignments!$G$2:$G$278=A11)/COUNTIFS(Assignments!$G$2:$G$278,Assignments!$G$2:$G$278,Assignments!$E$2:$E$278,Assignments!$E$2:$E$278)) | J11: =SUMPRODUCT((Assignments!$F$2:$F$278=A11)/COUNTIFS(Assignments!$F$2:$F$278,Assignments!$F$2:$F$278,Assignments!$E$2:$E$278,Assignments!$E$2:$E$278)) | K11: =COUNTIFS(Assignments!$G$2:$G$278,A11,Assignments!$N$2:$N$278,"Yes",Assignments!$L$2:$L$278,"No") | L11: =COUNTIFS(Assignments!$G$2:$G$278,A11,Assignments!$Q$2:$Q$278,"Yes") | M11: =ROUNDDOWN(E11*$R$2,0) | N11: =IF(L11>M11,"OVER BY "&(L11-M11),IF(O11>0,"Pending data","OK")) | O11: =COUNTIFS(Assignments!$G$2:$G$278,A11,Assignments!$Q$2:$Q$278,"Pending") | T11: =COUNTIFS(Assignments!$G$2:$G$278,$A11,Assignments!$N$2:$N$278,"Yes",Assignments!$AB$2:$AB$278,1) | U11: =COUNTIFS(Assignments!$G$2:$G$278,$A11,Assignments!$N$2:$N$278,"Yes",Assignments!$AB$2:$AB$278,2) | V11: =COUNTIFS(Assignments!$G$2:$G$278,$A11,Assignments!$N$2:$N$278,"Yes",Assignments!$AB$2:$AB$278,3) | W11: =COUNTIFS(Assignments!$G$2:$G$278,$A11,Assignments!$N$2:$N$278,"Yes",Assignments!$AB$2:$AB$278,4) | X11: =IFERROR((T11+U11)/COUNTIFS(Assignments!$G$2:$G$278,$A11,Assignments!$N$2:$N$278,"Yes"),"") | Y11: =SUMPRODUCT((Assignments!$G$2:$G$278=$A11)*(Assignments!$N$2:$N$278="Yes")*Assignments!$AD$2:$AD$278) | Z11: =SUMIFS(Assignments!$M$2:$M$278,Assignments!$G$2:$G$278,$A11,Assignments!$N$2:$N$278,"Yes",Assignments!$AB$2:$AB$278,3)
A12: =Lookups!A12 | B12: =Lookups!B12 | C12: =Lookups!C12 | D12: =Lookups!E12 | E12: =COUNTIFS(Assignments!$G$2:$G$278,A12,Assignments!$N$2:$N$278,"Yes") | F12: =$R$1 | G12: =IF(E12<=F12,"OK","OVER BY "&(E12-F12)) | H12: =SUMIFS(Assignments!$M$2:$M$278,Assignments!$G$2:$G$278,A12) | I12: =SUMPRODUCT((Assignments!$G$2:$G$278=A12)/COUNTIFS(Assignments!$G$2:$G$278,Assignments!$G$2:$G$278,Assignments!$E$2:$E$278,Assignments!$E$2:$E$278)) | J12: =SUMPRODUCT((Assignments!$F$2:$F$278=A12)/COUNTIFS(Assignments!$F$2:$F$278,Assignments!$F$2:$F$278,Assignments!$E$2:$E$278,Assignments!$E$2:$E$278)) | K12: =COUNTIFS(Assignments!$G$2:$G$278,A12,Assignments!$N$2:$N$278,"Yes",Assignments!$L$2:$L$278,"No") | L12: =COUNTIFS(Assignments!$G$2:$G$278,A12,Assignments!$Q$2:$Q$278,"Yes") | M12: =ROUNDDOWN(E12*$R$2,0) | N12: =IF(L12>M12,"OVER BY "&(L12-M12),IF(O12>0,"Pending data","OK")) | O12: =COUNTIFS(Assignments!$G$2:$G$278,A12,Assignments!$Q$2:$Q$278,"Pending") | T12: =COUNTIFS(Assignments!$G$2:$G$278,$A12,Assignments!$N$2:$N$278,"Yes",Assignments!$AB$2:$AB$278,1) | U12: =COUNTIFS(Assignments!$G$2:$G$278,$A12,Assignments!$N$2:$N$278,"Yes",Assignments!$AB$2:$AB$278,2) | V12: =COUNTIFS(Assignments!$G$2:$G$278,$A12,Assignments!$N$2:$N$278,"Yes",Assignments!$AB$2:$AB$278,3) | W12: =COUNTIFS(Assignments!$G$2:$G$278,$A12,Assignments!$N$2:$N$278,"Yes",Assignments!$AB$2:$AB$278,4) | X12: =IFERROR((T12+U12)/COUNTIFS(Assignments!$G$2:$G$278,$A12,Assignments!$N$2:$N$278,"Yes"),"") | Y12: =SUMPRODUCT((Assignments!$G$2:$G$278=$A12)*(Assignments!$N$2:$N$278="Yes")*Assignments!$AD$2:$AD$278) | Z12: =SUMIFS(Assignments!$M$2:$M$278,Assignments!$G$2:$G$278,$A12,Assignments!$N$2:$N$278,"Yes",Assignments!$AB$2:$AB$278,3)
A13: =Lookups!A13 | B13: =Lookups!B13 | C13: =Lookups!C13 | D13: =Lookups!E13 | E13: =COUNTIFS(Assignments!$G$2:$G$278,A13,Assignments!$N$2:$N$278,"Yes") | F13: =$R$1 | G13: =IF(E13<=F13,"OK","OVER BY "&(E13-F13)) | H13: =SUMIFS(Assignments!$M$2:$M$278,Assignments!$G$2:$G$278,A13) | I13: =SUMPRODUCT((Assignments!$G$2:$G$278=A13)/COUNTIFS(Assignments!$G$2:$G$278,Assignments!$G$2:$G$278,Assignments!$E$2:$E$278,Assignments!$E$2:$E$278)) | J13: =SUMPRODUCT((Assignments!$F$2:$F$278=A13)/COUNTIFS(Assignments!$F$2:$F$278,Assignments!$F$2:$F$278,Assignments!$E$2:$E$278,Assignments!$E$2:$E$278)) | K13: =COUNTIFS(Assignments!$G$2:$G$278,A13,Assignments!$N$2:$N$278,"Yes",Assignments!$L$2:$L$278,"No") | L13: =COUNTIFS(Assignments!$G$2:$G$278,A13,Assignments!$Q$2:$Q$278,"Yes") | M13: =ROUNDDOWN(E13*$R$2,0) | N13: =IF(L13>M13,"OVER BY "&(L13-M13),IF(O13>0,"Pending data","OK")) | O13: =COUNTIFS(Assignments!$G$2:$G$278,A13,Assignments!$Q$2:$Q$278,"Pending") | T13: =COUNTIFS(Assignments!$G$2:$G$278,$A13,Assignments!$N$2:$N$278,"Yes",Assignments!$AB$2:$AB$278,1) | U13: =COUNTIFS(Assignments!$G$2:$G$278,$A13,Assignments!$N$2:$N$278,"Yes",Assignments!$AB$2:$AB$278,2) | V13: =COUNTIFS(Assignments!$G$2:$G$278,$A13,Assignments!$N$2:$N$278,"Yes",Assignments!$AB$2:$AB$278,3) | W13: =COUNTIFS(Assignments!$G$2:$G$278,$A13,Assignments!$N$2:$N$278,"Yes",Assignments!$AB$2:$AB$278,4) | X13: =IFERROR((T13+U13)/COUNTIFS(Assignments!$G$2:$G$278,$A13,Assignments!$N$2:$N$278,"Yes"),"") | Y13: =SUMPRODUCT((Assignments!$G$2:$G$278=$A13)*(Assignments!$N$2:$N$278="Yes")*Assignments!$AD$2:$AD$278) | Z13: =SUMIFS(Assignments!$M$2:$M$278,Assignments!$G$2:$G$278,$A13,Assignments!$N$2:$N$278,"Yes",Assignments!$AB$2:$AB$278,3)
A14: =Lookups!A14 | B14: =Lookups!B14 | C14: =Lookups!C14 | D14: =Lookups!E14 | E14: =COUNTIFS(Assignments!$G$2:$G$278,A14,Assignments!$N$2:$N$278,"Yes") | F14: n/a | G14: Manager book | H14: =SUMIFS(Assignments!$M$2:$M$278,Assignments!$G$2:$G$278,A14) | I14: =SUMPRODUCT((Assignments!$G$2:$G$278=A14)/COUNTIFS(Assignments!$G$2:$G$278,Assignments!$G$2:$G$278,Assignments!$E$2:$E$278,Assignments!$E$2:$E$278)) | J14: =SUMPRODUCT((Assignments!$F$2:$F$278=A14)/COUNTIFS(Assignments!$F$2:$F$278,Assignments!$F$2:$F$278,Assignments!$E$2:$E$278,Assignments!$E$2:$E$278)) | K14: =COUNTIFS(Assignments!$G$2:$G$278,A14,Assignments!$N$2:$N$278,"Yes",Assignments!$L$2:$L$278,"No") | L14: =COUNTIFS(Assignments!$G$2:$G$278,A14,Assignments!$Q$2:$Q$278,"Yes") | M14: =ROUNDDOWN(E14*$R$2,0) | N14: =IF(L14>M14,"OVER BY "&(L14-M14),IF(O14>0,"Pending data","OK")) | O14: =COUNTIFS(Assignments!$G$2:$G$278,A14,Assignments!$Q$2:$Q$278,"Pending") | T14: =COUNTIFS(Assignments!$G$2:$G$278,$A14,Assignments!$N$2:$N$278,"Yes",Assignments!$AB$2:$AB$278,1) | U14: =COUNTIFS(Assignments!$G$2:$G$278,$A14,Assignments!$N$2:$N$278,"Yes",Assignments!$AB$2:$AB$278,2) | V14: =COUNTIFS(Assignments!$G$2:$G$278,$A14,Assignments!$N$2:$N$278,"Yes",Assignments!$AB$2:$AB$278,3) | W14: =COUNTIFS(Assignments!$G$2:$G$278,$A14,Assignments!$N$2:$N$278,"Yes",Assignments!$AB$2:$AB$278,4) | X14: =IFERROR((T14+U14)/COUNTIFS(Assignments!$G$2:$G$278,$A14,Assignments!$N$2:$N$278,"Yes"),"") | Y14: =SUMPRODUCT((Assignments!$G$2:$G$278=$A14)*(Assignments!$N$2:$N$278="Yes")*Assignments!$AD$2:$AD$278) | Z14: =SUMIFS(Assignments!$M$2:$M$278,Assignments!$G$2:$G$278,$A14,Assignments!$N$2:$N$278,"Yes",Assignments!$AB$2:$AB$278,3)
A15: Enterprise total | E15: =SUM(E2:E14) | H15: =SUM(H2:H14) | I15: =AVERAGE(I2:I13) | J15: =AVERAGEIF(J2:J13,">0") | K15: =SUM(K2:K14)
A16: AE counts include map gaps (open seats, no State AE shown, DC not on either map) as one counterpart each. Revised average covers the 12 XP seats including the open XP2; WIP average covers the 11 XPs with a WIP book. Both exclude Carolina Prieto's manager book.

Sheet Holds
A1: Hold | B1: Account | C1: Required | D1: Assigned XP | E1: Assigned Manager | F1: Result
A2: San Antonio stays with Steffany | B2: San Antonio, TX | C2: Steffany Amador | D2: =INDEX(Assignments!$G$2:$G$278,MATCH(B2,Assignments!$A$2:$A$278,0)) | E2: =INDEX(Assignments!$I$2:$I$278,MATCH(B2,Assignments!$A$2:$A$278,0)) | F2: =IF(D2=C2,"Met","BROKEN")
A3: DC stays with Paige | B3: District of Columbia | C3: Paige Wendle | D3: =INDEX(Assignments!$G$2:$G$278,MATCH(B3,Assignments!$A$2:$A$278,0)) | E3: =INDEX(Assignments!$I$2:$I$278,MATCH(B3,Assignments!$A$2:$A$278,0)) | F3: =IF(D3=C3,"Met","BROKEN")
A4: Denver held by a Savannah report | B4: Denver City and County, CO | C4: Savannah Lane | D4: =INDEX(Assignments!$G$2:$G$278,MATCH(B4,Assignments!$A$2:$A$278,0)) | E4: =INDEX(Assignments!$I$2:$I$278,MATCH(B4,Assignments!$A$2:$A$278,0)) | F4: =IF(E4=C4,"Met","BROKEN")
A5: Columbus held by an Ashley report | B5: Columbus OH | C5: Ashley Hill | D5: =INDEX(Assignments!$G$2:$G$278,MATCH(B5,Assignments!$A$2:$A$278,0)) | E5: =INDEX(Assignments!$I$2:$I$278,MATCH(B5,Assignments!$A$2:$A$278,0)) | F5: =IF(E5=C5,"Met","BROKEN")
A6: Colleen keeps Los Angeles | B6: Los Angeles, CA | C6: Colleen Moran | D6: =INDEX(Assignments!$G$2:$G$278,MATCH(B6,Assignments!$A$2:$A$278,0)) | E6: =INDEX(Assignments!$I$2:$I$278,MATCH(B6,Assignments!$A$2:$A$278,0)) | F6: =IF(D6=C6,"Met","BROKEN")
A7: Colleen keeps GLACVCD | B7: Greater Los Angeles County Vector Control District CA | C7: Colleen Moran | D7: =INDEX(Assignments!$G$2:$G$278,MATCH(B7,Assignments!$A$2:$A$278,0)) | E7: =INDEX(Assignments!$I$2:$I$278,MATCH(B7,Assignments!$A$2:$A$278,0)) | F7: =IF(D7=C7,"Met","BROKEN")
A8: Steffany takes Texas state | B8: Texas Department of Transportation (TXDOT) | C8: Steffany Amador | D8: =INDEX(Assignments!$G$2:$G$278,MATCH(B8,Assignments!$A$2:$A$278,0)) | E8: =INDEX(Assignments!$I$2:$I$278,MATCH(B8,Assignments!$A$2:$A$278,0)) | F8: =IF(D8=C8,"Met","BROKEN")
A9: Miami stays with Taylor | B9: Miami FL | C9: Taylor Roman | D9: =INDEX(Assignments!$G$2:$G$278,MATCH(B9,Assignments!$A$2:$A$278,0)) | E9: =INDEX(Assignments!$I$2:$I$278,MATCH(B9,Assignments!$A$2:$A$278,0)) | F9: =IF(D9=C9,"Met","BROKEN")
A10: Paige keeps Washington | B10: Washington Department of Transportation | C10: Paige Wendle | D10: =INDEX(Assignments!$G$2:$G$278,MATCH(B10,Assignments!$A$2:$A$278,0)) | E10: =INDEX(Assignments!$I$2:$I$278,MATCH(B10,Assignments!$A$2:$A$278,0)) | F10: =IF(D10=C10,"Met","BROKEN")
A11: Halena keeps Connecticut | B11: Connecticut Department of Administrative Services | C11: Halena Martin | D11: =INDEX(Assignments!$G$2:$G$278,MATCH(B11,Assignments!$A$2:$A$278,0)) | E11: =INDEX(Assignments!$I$2:$I$278,MATCH(B11,Assignments!$A$2:$A$278,0)) | F11: =IF(D11=C11,"Met","BROKEN")
A12: Halena keeps Maine | B12: Maine | C12: Halena Martin | D12: =INDEX(Assignments!$G$2:$G$278,MATCH(B12,Assignments!$A$2:$A$278,0)) | E12: =INDEX(Assignments!$I$2:$I$278,MATCH(B12,Assignments!$A$2:$A$278,0)) | F12: =IF(D12=C12,"Met","BROKEN")

Sheet AE Fan-out
A1: AE / SAM | B1: Map | C1: XPs Worked With (Revised) | D1: XPs Worked With (WIP) | E1: Countable Accounts | F1: ARR
A2: Andrew Wyzkoski | B2: Local ENT | C2: =SUMPRODUCT((Assignments!$E$2:$E$278=A2)/COUNTIFS(Assignments!$E$2:$E$278,Assignments!$E$2:$E$278,Assignments!$G$2:$G$278,Assignments!$G$2:$G$278)) | D2: =SUMPRODUCT((Assignments!$E$2:$E$278=A2)/COUNTIFS(Assignments!$E$2:$E$278,Assignments!$E$2:$E$278,Assignments!$F$2:$F$278,Assignments!$F$2:$F$278)) | E2: =COUNTIFS(Assignments!$E$2:$E$278,A2,Assignments!$N$2:$N$278,"Yes") | F2: =SUMIFS(Assignments!$M$2:$M$278,Assignments!$E$2:$E$278,A2)
A3: Austin Goodman | B3: Local ENT | C3: =SUMPRODUCT((Assignments!$E$2:$E$278=A3)/COUNTIFS(Assignments!$E$2:$E$278,Assignments!$E$2:$E$278,Assignments!$G$2:$G$278,Assignments!$G$2:$G$278)) | D3: =SUMPRODUCT((Assignments!$E$2:$E$278=A3)/COUNTIFS(Assignments!$E$2:$E$278,Assignments!$E$2:$E$278,Assignments!$F$2:$F$278,Assignments!$F$2:$F$278)) | E3: =COUNTIFS(Assignments!$E$2:$E$278,A3,Assignments!$N$2:$N$278,"Yes") | F3: =SUMIFS(Assignments!$M$2:$M$278,Assignments!$E$2:$E$278,A3)
A4: Bill Marshall | B4: Local ENT | C4: =SUMPRODUCT((Assignments!$E$2:$E$278=A4)/COUNTIFS(Assignments!$E$2:$E$278,Assignments!$E$2:$E$278,Assignments!$G$2:$G$278,Assignments!$G$2:$G$278)) | D4: =SUMPRODUCT((Assignments!$E$2:$E$278=A4)/COUNTIFS(Assignments!$E$2:$E$278,Assignments!$E$2:$E$278,Assignments!$F$2:$F$278,Assignments!$F$2:$F$278)) | E4: =COUNTIFS(Assignments!$E$2:$E$278,A4,Assignments!$N$2:$N$278,"Yes") | F4: =SUMIFS(Assignments!$M$2:$M$278,Assignments!$E$2:$E$278,A4)
A5: Carrie Breedlove | B5: Local ENT | C5: =SUMPRODUCT((Assignments!$E$2:$E$278=A5)/COUNTIFS(Assignments!$E$2:$E$278,Assignments!$E$2:$E$278,Assignments!$G$2:$G$278,Assignments!$G$2:$G$278)) | D5: =SUMPRODUCT((Assignments!$E$2:$E$278=A5)/COUNTIFS(Assignments!$E$2:$E$278,Assignments!$E$2:$E$278,Assignments!$F$2:$F$278,Assignments!$F$2:$F$278)) | E5: =COUNTIFS(Assignments!$E$2:$E$278,A5,Assignments!$N$2:$N$278,"Yes") | F5: =SUMIFS(Assignments!$M$2:$M$278,Assignments!$E$2:$E$278,A5)
A6: Carter Bradford | B6: Local ENT | C6: =SUMPRODUCT((Assignments!$E$2:$E$278=A6)/COUNTIFS(Assignments!$E$2:$E$278,Assignments!$E$2:$E$278,Assignments!$G$2:$G$278,Assignments!$G$2:$G$278)) | D6: =SUMPRODUCT((Assignments!$E$2:$E$278=A6)/COUNTIFS(Assignments!$E$2:$E$278,Assignments!$E$2:$E$278,Assignments!$F$2:$F$278,Assignments!$F$2:$F$278)) | E6: =COUNTIFS(Assignments!$E$2:$E$278,A6,Assignments!$N$2:$N$278,"Yes") | F6: =SUMIFS(Assignments!$M$2:$M$278,Assignments!$E$2:$E$278,A6)
A7: Cedric Simpkins | B7: Local ENT | C7: =SUMPRODUCT((Assignments!$E$2:$E$278=A7)/COUNTIFS(Assignments!$E$2:$E$278,Assignments!$E$2:$E$278,Assignments!$G$2:$G$278,Assignments!$G$2:$G$278)) | D7: =SUMPRODUCT((Assignments!$E$2:$E$278=A7)/COUNTIFS(Assignments!$E$2:$E$278,Assignments!$E$2:$E$278,Assignments!$F$2:$F$278,Assignments!$F$2:$F$278)) | E7: =COUNTIFS(Assignments!$E$2:$E$278,A7,Assignments!$N$2:$N$278,"Yes") | F7: =SUMIFS(Assignments!$M$2:$M$278,Assignments!$E$2:$E$278,A7)
A8: Conrad Taylor | B8: Local ENT | C8: =SUMPRODUCT((Assignments!$E$2:$E$278=A8)/COUNTIFS(Assignments!$E$2:$E$278,Assignments!$E$2:$E$278,Assignments!$G$2:$G$278,Assignments!$G$2:$G$278)) | D8: =SUMPRODUCT((Assignments!$E$2:$E$278=A8)/COUNTIFS(Assignments!$E$2:$E$278,Assignments!$E$2:$E$278,Assignments!$F$2:$F$278,Assignments!$F$2:$F$278)) | E8: =COUNTIFS(Assignments!$E$2:$E$278,A8,Assignments!$N$2:$N$278,"Yes") | F8: =SUMIFS(Assignments!$M$2:$M$278,Assignments!$E$2:$E$278,A8)
A9: Dallas SAM (open) | B9: Local ENT | C9: =SUMPRODUCT((Assignments!$E$2:$E$278=A9)/COUNTIFS(Assignments!$E$2:$E$278,Assignments!$E$2:$E$278,Assignments!$G$2:$G$278,Assignments!$G$2:$G$278)) | D9: =SUMPRODUCT((Assignments!$E$2:$E$278=A9)/COUNTIFS(Assignments!$E$2:$E$278,Assignments!$E$2:$E$278,Assignments!$F$2:$F$278,Assignments!$F$2:$F$278)) | E9: =COUNTIFS(Assignments!$E$2:$E$278,A9,Assignments!$N$2:$N$278,"Yes") | F9: =SUMIFS(Assignments!$M$2:$M$278,Assignments!$E$2:$E$278,A9)
A10: David Cliff | B10: Local ENT | C10: =SUMPRODUCT((Assignments!$E$2:$E$278=A10)/COUNTIFS(Assignments!$E$2:$E$278,Assignments!$E$2:$E$278,Assignments!$G$2:$G$278,Assignments!$G$2:$G$278)) | D10: =SUMPRODUCT((Assignments!$E$2:$E$278=A10)/COUNTIFS(Assignments!$E$2:$E$278,Assignments!$E$2:$E$278,Assignments!$F$2:$F$278,Assignments!$F$2:$F$278)) | E10: =COUNTIFS(Assignments!$E$2:$E$278,A10,Assignments!$N$2:$N$278,"Yes") | F10: =SUMIFS(Assignments!$M$2:$M$278,Assignments!$E$2:$E$278,A10)
A11: Desmond Davis | B11: Local ENT | C11: =SUMPRODUCT((Assignments!$E$2:$E$278=A11)/COUNTIFS(Assignments!$E$2:$E$278,Assignments!$E$2:$E$278,Assignments!$G$2:$G$278,Assignments!$G$2:$G$278)) | D11: =SUMPRODUCT((Assignments!$E$2:$E$278=A11)/COUNTIFS(Assignments!$E$2:$E$278,Assignments!$E$2:$E$278,Assignments!$F$2:$F$278,Assignments!$F$2:$F$278)) | E11: =COUNTIFS(Assignments!$E$2:$E$278,A11,Assignments!$N$2:$N$278,"Yes") | F11: =SUMIFS(Assignments!$M$2:$M$278,Assignments!$E$2:$E$278,A11)
A12: Jason Spanier | B12: Local ENT | C12: =SUMPRODUCT((Assignments!$E$2:$E$278=A12)/COUNTIFS(Assignments!$E$2:$E$278,Assignments!$E$2:$E$278,Assignments!$G$2:$G$278,Assignments!$G$2:$G$278)) | D12: =SUMPRODUCT((Assignments!$E$2:$E$278=A12)/COUNTIFS(Assignments!$E$2:$E$278,Assignments!$E$2:$E$278,Assignments!$F$2:$F$278,Assignments!$F$2:$F$278)) | E12: =COUNTIFS(Assignments!$E$2:$E$278,A12,Assignments!$N$2:$N$278,"Yes") | F12: =SUMIFS(Assignments!$M$2:$M$278,Assignments!$E$2:$E$278,A12)
A13: Jeff Gaisford | B13: Local ENT | C13: =SUMPRODUCT((Assignments!$E$2:$E$278=A13)/COUNTIFS(Assignments!$E$2:$E$278,Assignments!$E$2:$E$278,Assignments!$G$2:$G$278,Assignments!$G$2:$G$278)) | D13: =SUMPRODUCT((Assignments!$E$2:$E$278=A13)/COUNTIFS(Assignments!$E$2:$E$278,Assignments!$E$2:$E$278,Assignments!$F$2:$F$278,Assignments!$F$2:$F$278)) | E13: =COUNTIFS(Assignments!$E$2:$E$278,A13,Assignments!$N$2:$N$278,"Yes") | F13: =SUMIFS(Assignments!$M$2:$M$278,Assignments!$E$2:$E$278,A13)
... A39: Todd Bowers | B39: State | C39: =SUMPRODUCT((Assignments!$E$2:$E$278=A39)/COUNTIFS(Assignments!$E$2:$E$278,Assignments!$E$2:$E$278,Assignments!$G$2:$G$278,Assignments!$G$2:$G$278)) | D39: =SUMPRODUCT((Assignments!$E$2:$E$278=A39)/COUNTIFS(Assignments!$E$2:$E$278,Assignments!$E$2:$E$278,Assignments!$F$2:$F$278,Assignments!$F$2:$F$278)) | E39: =COUNTIFS(Assignments!$E$2:$E$278,A39,Assignments!$N$2:$N$278,"Yes") | F39: =SUMIFS(Assignments!$M$2:$M$278,Assignments!$E$2:$E$278,A39)

Sheet Growth Tiers
A1: State | B1: State-agency tier | C1: State-agency score | D1: State accts in book | E1: Local ENT tier | F1: Local ENT score | G1: Local accts in book | H1: Tiers disagree | I1: Jurisdictions 100k+ | J1: Held in this book | K1: Fiscal posture | L1: Rainy day % of spend | M1: Budget cycle | N1: IT modernization signal | O1: Grant environment | P1: ARPA cliff exposure | Q1: Purchasing access | R1: League channel taken | S1: Local capacity | T1: Property tax cap | U1: Population | V1: Pop % chg | W1: Domestic mig / 1k | X1: Research confidence | Y1: State ARR | Z1: Local ARR
A2: Texas | B2: A | C2: 82.4 | D2: 13 | E2: A | F2: 63.1 | G2: 10 | I2: 87 | J2: 10 | K2: Stable | L2: 23.3 | M2: Biennial | N2: funded | O2: thin | P2: med | Q2: strong | S2: typical | T2: yes | U2: 31709821 | V2: 1.25 | W2: 2.12 | X2: med | Y2: 2013624 | Z2: 2823033
A3: Virginia | B3: A | C3: 78.8 | D3: 1 | E3: A | F3: 63.9 | G3: 2 | I3: 18 | J3: 2 | K3: Stable | L3: 12.4 | M3: Biennial | N3: funded | O3: rich | P3: med | Q3: strong | S3: typical | U3: 8880107 | V3: 0.69 | W3: 0.71 | X3: high | Y3: 82354 | Z3: 831127
A4: Georgia | B4: A | C4: 77.5 | D4: 5 | E4: A | F4: 61.3 | G4: 2 | I4: 36 | J4: 2 | K4: Stable | L4: 15.4 | M4: Annual | N4: funded | O4: moderate | P4: med | Q4: present | R4: yes | S4: typical | U4: 11302748 | V4: 0.88 | W4: 2.42 | X4: low | Y4: 328232 | Z4: 406859
A5: Ohio | B5: A | C5: 74.7 | D5: 2 | E5: B | F5: 47 | G5: 3 | H5: yes | I5: 32 | J5: 3 | K5: Stable | L5: 12.6 | M5: Biennial | N5: funded | O5: moderate | P5: med | Q5: present | S5: constrained | U5: 11900510 | V5: 0.34 | W5: 1 | X5: med | Y5: 205769 | Z5: 1782145
A6: Pennsylvania | B6: A | C6: 72.6 | D6: 0 | E6: B | F6: 57.9 | G6: 3 | H6: yes | I6: 34 | J6: 3 | K6: Distressed | L6: 15.5 | M6: Annual | N6: funded | O6: moderate | P6: med | Q6: strong | S6: constrained | U6: 13059432 | V6: 0.1 | W6: -0.22 | X6: med | Y6: 0 | Z6: 286025
A7: Washington | B7: D | C7: 33.6 | D7: 5 | E7: A | F7: 70.1 | G7: 0 | H7: yes | I7: 23 | J7: 0 | K7: Distressed | L7: 2.8 | M7: Biennial | N7: none | O7: rich | P7: med | Q7: present | S7: typical | U7: 8001020 | V7: 0.92 | W7: 1.15 | X7: med | Y7: 994013 | Z7: 0
A8: Minnesota | B8: A | C8: 67.4 | D8: 4 | E8: A | F8: 58.5 | G8: 2 | I8: 15 | J8: 2 | K8: Constrained | L8: 10.6 | M8: Biennial | N8: funded | O8: rich | P8: med | Q8: strong | S8: constrained | U8: 5830405 | V8: 0.57 | W8: 1.42 | X8: med | Y8: 136946 | Z8: 403270
A9: New Mexico | B9: A | C9: 67 | D9: 7 | E9: B | F9: 53.4 | G9: 1 | H9: yes | I9: 8 | J9: 1 | K9: Expanding | L9: 24.1 | M9: Annual | N9: funded | O9: moderate | P9: med | Q9: present | S9: typical | U9: 2125498 | V9: -0.06 | W9: -1.07 | X9: low | Y9: 383693 | Z9: 90042
A10: Utah | B10: B | C10: 57.5 | D10: 1 | E10: A | F10: 66.6 | G10: 0 | H10: yes | I10: 11 | J10: 0 | K10: Stable | L10: 10.9 | M10: Annual | N10: none | O10: moderate | P10: low–med | Q10: present | S10: typical | U10: 3538904 | V10: 1.03 | W10: 0.94 | X10: med | Y10: 95340 | Z10: 0
A11: Montana | B11: A | C11: 65.8 | D11: 0 | E11: B | F11: 48.3 | G11: 0 | H11: yes | I11: 5 | J11: 0 | K11: Stable | L11: 15.3 | M11: Biennial | N11: funded | O11: thin | P11: high | Q11: present | S11: constrained | T11: yes | U11: 1144694 | V11: 0.63 | W11: 5.55 | X11: low | Y11: 0 | Z11: 0
A12: Massachusetts | B12: A | C12: 61.8 | D12: 1 | E12: A | F12: 65.3 | G12: 0 | I12: 20 | J12: 0 | K12: Stable | L12: 15.8 | M12: Annual | N12: none | O12: rich | P12: low | Q12: present | S12: typical | U12: 7154084 | V12: 0.22 | W12: -4.66 | X12: med | Y12: 214644 | Z12: 0
A13: Arkansas | B13: A | C13: 65.2 | D13: 0 | E13: B | F13: 55.3 | G13: 0 | H13: yes | I13: 9 | J13: 0 | K13: Expanding | L13: 27.9 | M13: Annual | N13: none | O13: thin | P13: med | Q13: coop_only | S13: typical | U13: 3114791 | V13: 0.6 | W13: 4.65 | X13: low | Y13: 0 | Z13: 0
A14: New York | B14: B | C14: 57 | D14: 2 | E14: A | F14: 64.9 | G14: 3 | H14: yes | I14: 34 | J14: 3 | K14: Constrained | L14: 7.7 | M14: Annual | N14: none | O14: rich | P14: low (state) / med (nyc & locals) | Q14: strong | S14: constrained | U14: 20002427 | V14: 0.01 | W14: -6.88 | X14: med | Y14: 1632532 | Z14: 226709
A15: North Carolina | B15: A | C15: 62.1 | D15: 0 | E15: A | F15: 64.9 | G15: 2 | I15: 39 | J15: 2 | K15: Stable | L15: 11.1 | M15: Biennial | N15: none | O15: moderate | P15: med | Q15: present | R15: yes | S15: constrained | U15: 11197968 | V15: 1.32 | W15: 7.51 | X15: low | Y15: 0 | Z15: 202481
A16: Indiana | B16: B | C16: 51.8 | D16: 0 | E16: A | F16: 63.7 | G16: 1 | H16: yes | I16: 24 | J16: 1 | K16: Constrained | L16: 9.5 | M16: Biennial | N16: none | O16: moderate | P16: med | Q16: present | S16: typical | U16: 6973333 | V16: 0.56 | W16: 1.75 | X16: low | Y16: 0 | Z16: 70972
A17: Michigan | B17: A | C17: 62.7 | D17: 0 | E17: B | F17: 49.5 | G17: 1 | H17: yes | I17: 27 | J17: 1 | K17: Constrained | L17: 13.1 | M17: Annual | N17: none | O17: moderate | P17: high | Q17: strong | S17: constrained | U17: 10127884 | V17: 0.28 | W17: 0.18 | X17: med | Y17: 0 | Z17: 489446
A18: California | B18: B | C18: 54.4 | D18: 16 | E18: A | F18: 62.3 | G18: 10 | H18: yes | I18: 112 | J18: 10 | K18: Distressed | L18: 17.4 | M18: Annual | N18: neutral | O18: rich | P18: low–med | Q18: present | R18: yes | S18: typical | U18: 39355309 | V18: -0.02 | W18: -5.82 | X18: med | Y18: 3303459 | Z18: 3907669
A19: Florida | B19: A | C19: 62 | D19: 4 | E19: B | F19: 57.8 | G19: 13 | H19: yes | I19: 63 | J19: 13 | K19: Constrained | L19: 8.6 | M19: Annual | N19: governance | O19: rich | P19: med | Q19: present | S19: typical | T19: yes | U19: 23462518 | V19: 0.85 | W19: 0.96 | X19: med | Y19: 505348 | Z19: 2567452
A20: Idaho | B20: C | C20: 42.3 | D20: 1 | E20: A | F20: 59.7 | G20: 0 | H20: yes | I20: 7 | J20: 0 | K20: Constrained | L20: 21.3 | M20: Annual | N20: headwind | O20: thin | P20: med | Q20: coop_only | S20: typical | U20: 2029733 | V20: 1.44 | W20: 9.81 | X20: low | Y20: 88765 | Z20: 0
A21: Alabama | B21: A | C21: 58.4 | D21: 1 | E21: B | F21: 55.1 | G21: 1 | H21: yes | I21: 19 | J21: 1 | K21: Stable | L21: 19.5 | M21: Annual | N21: none | O21: moderate | P21: med | Q21: coop_only | R21: yes | S21: typical | U21: 5193088 | V21: 0.58 | W21: 4.5 | X21: low | Y21: 75086 | Z21: 57780
A22: Wisconsin | B22: B | C22: 57.8 | D22: 2 | E22: C | F22: 44.7 | G22: 3 | H22: yes | I22: 19 | J22: 3 | K22: Stable | L22: 9.3 | M22: Biennial | N22: none | O22: moderate | P22: high | Q22: present | R22: yes | S22: constrained | U22: 5972787 | V22: 0.26 | W22: 1.17 | X22: med | Y22: 53544 | Z22: 429986
A23: Oklahoma | B23: B | C23: 57.6 | D23: 2 | E23: B | F23: 52 | G23: 1 | I23: 11 | J23: 1 | K23: Constrained | L23: 17.1 | M23: Annual | N23: none | O23: thin | P23: high | Q23: strong | S23: typical | U23: 4123288 | V23: 0.62 | W23: 3.51 | X23: med | Y23: 79354 | Z23: 300031
A24: Arizona | B24: C | C24: 46.6 | D24: 7 | E24: B | F24: 57.3 | G24: 3 | H24: yes | I24: 23 | J24: 3 | K24: Constrained | L24: 9.1 | M24: Annual | N24: headwind | O24: moderate | P24: med | Q24: present | S24: typical | U24: 7623818 | V24: 0.89 | W24: 4.08 | X24: low | Y24: 598447 | Z24: 366230
A25: Maryland | B25: B | C25: 52 | D25: 0 | E25: B | F25: 56.3 | G25: 2 | I25: 15 | J25: 2 | K25: Distressed | L25: 7.8 | M25: Annual | N25: headwind | O25: rich | P25: med | Q25: strong | R25: yes | S25: typical | U25: 6265347 | V25: 0.32 | W25: -1.94 | X25: high | Y25: 0 | Z25: 256954
A26: Mississippi | B26: B | C26: 54.8 | D26: 0 | E26: C | F26: 46.9 | G26: 0 | H26: yes | I26: 7 | J26: 0 | K26: Stable | L26: 9.9 | M26: Annual | N26: none | O26: thin | P26: high | Q26: coop_only | S26: typical | U26: 2954160 | V26: 0.14 | W26: -0.31 | X26: med | Y26: 0 | Z26: 0
A27: Delaware | B27: C | C27: 41 | D27: 0 | E27: B | F27: 54.2 | G27: 0 | H27: yes | I27: 3 | J27: 0 | K27: Constrained | L27: 5.1 | M27: Annual | N27: none | O27: moderate | P27: high | Q27: coop_only | S27: typical | U27: 1059952 | V27: 0.94 | W27: 6.47 | X27: low | Y27: 0 | Z27: 0
A28: New Jersey | B28: C | C28: 42.5 | D28: 2 | E28: B | F28: 54 | G28: 1 | H28: yes | I28: 23 | J28: 1 | K28: Distressed | L28: 0 | M28: Annual | N28: none | O28: rich | P28: high | Q28: coop_only | S28: typical | U28: 9548215 | V28: 0.44 | W28: -3.92 | X28: high | Y28: 227906 | Z28: 23334
A29: Nevada | B29: B | C29: 49.1 | D29: 3 | E29: B | F29: 53.3 | G29: 0 | I29: 7 | J29: 0 | K29: Stable | L29: 18.5 | M29: Biennial | N29: none | O29: moderate | P29: high | Q29: coop_only | S29: typical | U29: 3282188 | V29: 0.88 | W29: 4.54 | X29: med | Y29: 163668 | Z29: 0
A30: Maine | B30: D | C30: 26.9 | D30: 2 | E30: B | F30: 52.9 | G30: 0 | H30: yes | I30: 5 | J30: 0 | K30: Constrained | L30: 13.2 | M30: Biennial | N30: none | O30: moderate | P30: high | Q30: coop_only | S30: constrained | U30: 1414874 | V30: 0.46 | W30: 5.23 | X30: med | Y30: 356387 | Z30: 0
A31: Illinois | B31: B | C31: 52.2 | D31: 1 | E31: C | F31: 40 | G31: 4 | H31: yes | I31: 27 | J31: 4 | K31: Constrained | L31: 4.5 | M31: Annual | N31: none | O31: moderate | P31: med | Q31: coop_only | S31: constrained | U31: 12719141 | V31: 0.13 | W31: -3.15 | X31: med | Y31: 76184 | Z31: 1666026
A32: District of Columbia | B32: D | C32: 34.3 | D32: 0 | E32: B | F32: 51.7 | G32: 1 | H32: yes | I32: 1 | J32: 0 | K32: Distressed | L32: 8.2 | M32: Annual | N32: none | O32: moderate | P32: low | Q32: coop_only | S32: typical | U32: 693645 | V32: 0.34 | W32: -5.95 | X32: med | Y32: 0 | Z32: 0
A33: Connecticut | B33: C | C33: 40.5 | D33: 4 | E33: B | F33: 51.4 | G33: 0 | H33: yes | I33: 13 | J33: 0 | K33: Stable | L33: 18.8 | M33: Biennial | N33: none | O33: moderate | P33: med | Q33: coop_only | R33: yes | S33: typical | U33: 3688496 | V33: 0.38 | W33: -1.61 | X33: med | Y33: 745164 | Z33: 0
A34: South Carolina | B34: B | C34: 51 | D34: 0 | E34: B | F34: 51.3 | G34: 1 | I34: 19 | J34: 1 | K34: Constrained | L34: 13.8 | M34: Annual | N34: none | O34: thin | P34: high | Q34: coop_only | R34: yes | S34: typical | U34: 5570274 | V34: 1.46 | W34: 11.96 | X34: med | Y34: 0 | Z34: 237874
A35: Iowa | B35: C | C35: 42.3 | D35: 1 | E35: B | F35: 50.3 | G35: 1 | H35: yes | I35: 11 | J35: 1 | K35: Constrained | L35: 9 | M35: Annual | N35: none | O35: moderate | P35: med | Q35: strong | R35: yes | S35: constrained | U35: 3238387 | V35: 0.25 | W35: -0.3 | X35: low | Y35: 511995 | Z35: 89731
A36: Colorado | B36: C | C36: 42.5 | D36: 4 | E36: B | F36: 50.1 | G36: 2 | H36: yes | I36: 24 | J36: 2 | K36: Distressed | L36: 9 | M36: Annual | N36: headwind | O36: rich | P36: med | Q36: present | S36: typical | T36: yes | U36: 6012561 | V36: 0.4 | W36: -2.01 | X36: high | Y36: 307639 | Z36: 702396
A37: South Dakota | B37: B | C37: 49.9 | D37: 0 | E37: B | F37: 48.8 | G37: 0 | I37: 3 | J37: 0 | K37: Stable | L37: 12.4 | M37: Annual | N37: none | O37: thin | P37: high | Q37: coop_only | S37: constrained | U37: 935094 | V37: 0.86 | W37: 2.32 | X37: low | Y37: 0 | Z37: 0
A38: Kentucky | B38: D | C38: 34.7 | D38: 12 | E38: B | F38: 49.1 | G38: 1 | H38: yes | I38: 11 | J38: 1 | K38: Constrained | L38: 22.5 | M38: Biennial | N38: none | O38: moderate | P38: med | Q38: coop_only | S38: typical | U38: 4606864 | V38: 0.5 | W38: 1.58 | X38: low | Y38: 936944 | Z38: 72050
A39: Rhode Island | B39: C | C39: 41.3 | D39: 0 | E39: B | F39: 48.8 | G39: 0 | H39: yes | I39: 4 | J39: 0 | K39: Constrained | L39: 5.2 | M39: Annual | N39: none | O39: moderate | P39: high | Q39: coop_only | S39: typical | U39: 1114521 | V39: 0.37 | W39: -1.39 | X39: low | Y39: 0 | Z39: 0
A40: Tennessee | B40: B | C40: 47.9 | D40: 1 | E40: B | F40: 48.7 | G40: 2 | I40: 23 | J40: 2 | K40: Constrained | L40: 8.5 | M40: Annual | N40: none | O40: moderate | P40: high | Q40: coop_only | R40: yes | S40: typical | U40: 7315076 | V40: 0.88 | W40: 5.79 | X40: med | Y40: 244500 | Z40: 667398
...

Sheet Lookups
A1: XP | B1: Manager (Scenario A) | C1: Level | D1: Location | E1: XP Time Zone | G1: Time Zone | H1: Offset
A2: Paige Wendle | B2: Savannah Lane | C2: XP3 | D2: Idaho | E2: MT | G2: PT | H2: 0
A3: Colleen Moran | B3: Ashley Hill | C3: XP3 | D3: Nevada | E3: PT | G3: MT | H3: 1
A4: Open XP2 (PT) | B4: TBD | C4: XP2 | D4: Open headcount, Pacific | E4: PT | G4: CT | H4: 2
A5: Cody Nichols | B5: Ashley Hill | C5: XP1 | D5: Costa Rica | E5: CT | G5: ET | H5: 3
A6: Alejandro Solano | B6: Ashley Hill | C6: XP1 | D6: Costa Rica | E6: CT
A7: Taylor Roman | B7: Savannah Lane | C7: XP3 | D7: Miami, FL | E7: ET
A8: Marcy Castro | B8: Ashley Hill | C8: XP1 | D8: Costa Rica | E8: CT | G8: Offsets are hours relative to Pacific. Source: standard US time zones; Costa Rica treated as Central.
A9: Brooke Minichino | B9: Savannah Lane | C9: XP2 | D9: Washington, DC | E9: ET
A10: Steffany Amador | B10: Ashley Hill | C10: XP3 | D10: North Carolina | E10: ET
A11: Halena Martin | B11: Savannah Lane | C11: XP3 | D11: Pennsylvania | E11: ET
A12: Andy O'Brien | B12: Savannah Lane | C12: XP3 | D12: Virginia | E12: ET
A13: Carolina Cambronero | B13: Savannah Lane | C13: XP3 | D13: Costa Rica | E13: CT
A14: Carolina Prieto | B14: Carolina Prieto (manager book) | C14: Manager | D14: Not specified | E14: n/a

Sheet Assignments
A1: Account Name | B1: Ultimate Parent | C1: State | D1: Map | E1: AE / SAM | F1: WIP Proposed XP | G1: Revised XP | H1: Moved vs WIP | I1: Revised Manager | J1: XP Time Zone | K1: Account Time Zone | L1: Time Zone Fit | M1: ARR | N1: Counts vs Cap | O1: Capabilities (#) | P1: Service Cloud Advanced (Y/N) | Q1: Complex Account | R1: Mapping Note | S1: Current XP (9/21 export) | T1: Market Segment (export) | U1: Capabilities Counted | V1: Complex threshold | W1: 7 | X1: Territory Tier | Y1: Territory Score | Z1: Capability Whitespace | AA1: Growth Potential | AB1: Growth Tier | AC1: Growth Tier Label | AD1: Growth Load | AE1: Capability Data
A2: Denver City and County, CO | B2: Denver City and County, CO | C2: CO | D2: Local ENT | E2: David Cliff | F2: Steffany Amador | G2: Paige Wendle | H2: =IF(F2="(not in WIP)","New to Enterprise",IF(F2=G2,"No","Yes")) | I2: =IFERROR(INDEX(Lookups!$B$2:$B$14,MATCH(G2,Lookups!$A$2:$A$14,0)),"Not found") | J2: =IFERROR(INDEX(Lookups!$E$2:$E$14,MATCH(G2,Lookups!$A$2:$A$14,0)),"") | K2: MT | L2: =IF(J2="n/a","n/a",IFERROR(IF(ABS(INDEX(Lookups!$H$2:$H$5,MATCH(J2,Lookups!$G$2:$G$5,0))-INDEX(Lookups!$H$2:$H$5,MATCH(K2,Lookups!$G$2:$G$5,0)))<=1,"Yes","No"),"Check")) | M2: 370850.21 | N2: Yes | O2: 4 | Q2: =IF(N2<>"Yes","n/a",IF(OR(AND(O2<>"",O2>$W$1),P2="Y"),"Yes",IF(O2<>"","No","Pending"))) | S2: Steffany Amador | T2: Local ENT | U2: Agenda & Video, Forms & Workflows, Websites, Portals, & Intranets, govXCloud | X2: B | Y2: 50.1 | Z2: 0.5 | AA2: 0.5006 | AB2: 3 | AC2: Defend | AD2: 0.5 | AE2: reported
A3: Arapahoe County CO | B3: Arapahoe County CO | C3: CO | D3: Local ENT | E3: David Cliff | F3: Steffany Amador | G3: Paige Wendle | H3: =IF(F3="(not in WIP)","New to Enterprise",IF(F3=G3,"No","Yes")) | I3: =IFERROR(INDEX(Lookups!$B$2:$B$14,MATCH(G3,Lookups!$A$2:$A$14,0)),"Not found") | J3: =IFERROR(INDEX(Lookups!$E$2:$E$14,MATCH(G3,Lookups!$A$2:$A$14,0)),"") | K3: MT | L3: =IF(J3="n/a","n/a",IFERROR(IF(ABS(INDEX(Lookups!$H$2:$H$5,MATCH(J3,Lookups!$G$2:$G$5,0))-INDEX(Lookups!$H$2:$H$5,MATCH(K3,Lookups!$G$2:$G$5,0)))<=1,"Yes","No"),"Check")) | M3: 331546.29 | N3: Yes | O3: 7 | Q3: =IF(N3<>"Yes","n/a",IF(OR(AND(O3<>"",O3>$W$1),P3="Y"),"Yes",IF(O3<>"","No","Pending"))) | S3: Steffany Amador | T3: Local ENT | U3: Agenda & Video, Email & SMS, Engagement & Sentiment, Forms & Workflows, Recurring Services, Short-term Rentals, Websites, Portals, & Intranets | X3: B | Y3: 50.1 | Z3: 0.125 | AA3: 0.3506 | AB3: 3 | AC3: Defend | AD3: 0.5 | AE3: reported
A4: District of Columbia | B4: District of Columbia | C4: DC | D4: Neither map | E4: Not on either map | F4: Paige Wendle | G4: Paige Wendle | H4: =IF(F4="(not in WIP)","New to Enterprise",IF(F4=G4,"No","Yes")) | I4: =IFERROR(INDEX(Lookups!$B$2:$B$14,MATCH(G4,Lookups!$A$2:$A$14,0)),"Not found") | J4: =IFERROR(INDEX(Lookups!$E$2:$E$14,MATCH(G4,Lookups!$A$2:$A$14,0)),"") | K4: ET | L4: =IF(J4="n/a","n/a",IFERROR(IF(ABS(INDEX(Lookups!$H$2:$H$5,MATCH(J4,Lookups!$G$2:$G$5,0))-INDEX(Lookups!$H$2:$H$5,MATCH(K4,Lookups!$G$2:$G$5,0)))<=1,"Yes","No"),"Check")) | M4: 725132.5 | N4: Yes | O4: 4 | Q4: =IF(N4<>"Yes","n/a",IF(OR(AND(O4<>"",O4>$W$1),P4="Y"),"Yes",IF(O4<>"","No","Pending"))) | S4: Paige Wendle | T4: Federal | U4: Email & SMS, Engagement & Sentiment, Public Records Request, Recurring Services | X4: B | Y4: 51.7 | Z4: 0.5 | AA4: 0.5102 | AB4: 3 | AC4: Defend | AD4: 0.5 | AE4: reported
A5: Idaho Labor Department | B5: Idaho | C5: ID | D5: State | E5: Scott Mark | F5: Paige Wendle | G5: Paige Wendle | H5: =IF(F5="(not in WIP)","New to Enterprise",IF(F5=G5,"No","Yes")) | I5: =IFERROR(INDEX(Lookups!$B$2:$B$14,MATCH(G5,Lookups!$A$2:$A$14,0)),"Not found") | J5: =IFERROR(INDEX(Lookups!$E$2:$E$14,MATCH(G5,Lookups!$A$2:$A$14,0)),"") | K5: MT | L5: =IF(J5="n/a","n/a",IFERROR(IF(ABS(INDEX(Lookups!$H$2:$H$5,MATCH(J5,Lookups!$G$2:$G$5,0))-INDEX(Lookups!$H$2:$H$5,MATCH(K5,Lookups!$G$2:$G$5,0)))<=1,"Yes","No"),"Check")) | M5: 88765.39 | N5: Yes | O5: 3 | Q5: =IF(N5<>"Yes","n/a",IF(OR(AND(O5<>"",O5>$W$1),P5="Y"),"Yes",IF(O5<>"","No","Pending"))) | S5: Paige Wendle | T5: State | U5: Email & SMS, Engagement & Sentiment, Recurring Services | X5: C | Y5: 42.3 | Z5: 0.625 | AA5: 0.5038 | AB5: 4 | AC5: Maintain | AD5: 0.3 | AE5: reported
A6: Washington County OR | B6: Washington County OR | C6: OR | D6: Local ENT | E6: Carrie Breedlove | F6: Paige Wendle | G6: Paige Wendle | H6: =IF(F6="(not in WIP)","New to Enterprise",IF(F6=G6,"No","Yes")) | I6: =IFERROR(INDEX(Lookups!$B$2:$B$14,MATCH(G6,Lookups!$A$2:$A$14,0)),"Not found") | J6: =IFERROR(INDEX(Lookups!$E$2:$E$14,MATCH(G6,Lookups!$A$2:$A$14,0)),"") | K6: PT | L6: =IF(J6="n/a","n/a",IFERROR(IF(ABS(INDEX(Lookups!$H$2:$H$5,MATCH(J6,Lookups!$G$2:$G$5,0))-INDEX(Lookups!$H$2:$H$5,MATCH(K6,Lookups!$G$2:$G$5,0)))<=1,"Yes","No"),"Check")) | M6: 229991.53 | N6: Yes | O6: 6 | Q6: =IF(N6<>"Yes","n/a",IF(OR(AND(O6<>"",O6>$W$1),P6="Y"),"Yes",IF(O6<>"","No","Pending"))) | S6: Brooke Minichino | T6: Local ENT | U6: Agenda & Video, Channel Shift, Email & SMS, Engagement & Sentiment, Public Records Request, Recurring Services | X6: C | Y6: 46 | Z6: 0.25 | AA6: 0.376 | AB6: 3 | AC6: Defend | AD6: 0.5 | AE6: reported
A7: Tri-County Metropolitan Transportation District of Oregon (TriMet) | B7: Multnomah County OR | C7: OR | D7: Local ENT | E7: Carrie Breedlove | F7: (not in WIP) | G7: Paige Wendle | H7: =IF(F7="(not in WIP)","New to Enterprise",IF(F7=G7,"No","Yes")) | I7: =IFERROR(INDEX(Lookups!$B$2:$B$14,MATCH(G7,Lookups!$A$2:$A$14,0)),"Not found") | J7: =IFERROR(INDEX(Lookups!$E$2:$E$14,MATCH(G7,Lookups!$A$2:$A$14,0)),"") | K7: PT | L7: =IF(J7="n/a","n/a",IFERROR(IF(ABS(INDEX(Lookups!$H$2:$H$5,MATCH(J7,Lookups!$G$2:$G$5,0))-INDEX(Lookups!$H$2:$H$5,MATCH(K7,Lookups!$G$2:$G$5,0)))<=1,"Yes","No"),"Check")) | M7: 180702.45 | N7: Yes | O7: 2 | Q7: =IF(N7<>"Yes","n/a",IF(OR(AND(O7<>"",O7>$W$1),P7="Y"),"Yes",IF(O7<>"","No","Pending"))) | S7: Natalia Sanchez | T7: Local ENT | U7: Email & SMS, Public Records Request | X7: C | Y7: 46 | Z7: 0.75 | AA7: 0.576 | AB7: 3 | AC7: Defend | AD7: 0.5 | AE7: reported
A8: Oregon Department of Corrections | B8: Oregon | C8: OR | D8: State | E8: Todd Bowers | F8: Paige Wendle | G8: Paige Wendle | H8: =IF(F8="(not in WIP)","New to Enterprise",IF(F8=G8,"No","Yes")) | I8: =IFERROR(INDEX(Lookups!$B$2:$B$14,MATCH(G8,Lookups!$A$2:$A$14,0)),"Not found") | J8: =IFERROR(INDEX(Lookups!$E$2:$E$14,MATCH(G8,Lookups!$A$2:$A$14,0)),"") | K8: PT | L8: =IF(J8="n/a","n/a",IFERROR(IF(ABS(INDEX(Lookups!$H$2:$H$5,MATCH(J8,Lookups!$G$2:$G$5,0))-INDEX(Lookups!$H$2:$H$5,MATCH(K8,Lookups!$G$2:$G$5,0)))<=1,"Yes","No"),"Check")) | M8: 72622 | N8: Yes | O8: 4 | Q8: =IF(N8<>"Yes","n/a",IF(OR(AND(O8<>"",O8>$W$1),P8="Y"),"Yes",IF(O8<>"","No","Pending"))) | S8: Paige Wendle | T8: State | U8: Email & SMS, Engagement & Sentiment, Public Records Request, Recurring Services | X8: C | Y8: 42 | Z8: 0.5 | AA8: 0.452 | AB8: 4 | AC8: Maintain | AD8: 0.3 | AE8: reported
A9: Oregon Housing and Community Services | B9: Oregon | C9: OR | D9: State | E9: Todd Bowers | F9: Paige Wendle | G9: Paige Wendle | H9: =IF(F9="(not in WIP)","New to Enterprise",IF(F9=G9,"No","Yes")) | I9: =IFERROR(INDEX(Lookups!$B$2:$B$14,MATCH(G9,Lookups!$A$2:$A$14,0)),"Not found") | J9: =IFERROR(INDEX(Lookups!$E$2:$E$14,MATCH(G9,Lookups!$A$2:$A$14,0)),"") | K9: PT | L9: =IF(J9="n/a","n/a",IFERROR(IF(ABS(INDEX(Lookups!$H$2:$H$5,MATCH(J9,Lookups!$G$2:$G$5,0))-INDEX(Lookups!$H$2:$H$5,MATCH(K9,Lookups!$G$2:$G$5,0)))<=1,"Yes","No"),"Check")) | M9: 64326.23 | N9: Yes | O9: 2 | Q9: =IF(N9<>"Yes","n/a",IF(OR(AND(O9<>"",O9>$W$1),P9="Y"),"Yes",IF(O9<>"","No","Pending"))) | S9: Kerrian Dailey | T9: State | U9: Other, Public Records Request | X9: C | Y9: 42 | Z9: 0.75 | AA9: 0.552 | AB9: 4 | AC9: Maintain | AD9: 0.3 | AE9: reported
A10: Oregon Public Utility Commission | B10: Oregon | C10: OR | D10: State | E10: Todd Bowers | F10: Paige Wendle | G10: Paige Wendle | H10: =IF(F10="(not in WIP)","New to Enterprise",IF(F10=G10,"No","Yes")) | I10: =IFERROR(INDEX(Lookups!$B$2:$B$14,MATCH(G10,Lookups!$A$2:$A$14,0)),"Not found") | J10: =IFERROR(INDEX(Lookups!$E$2:$E$14,MATCH(G10,Lookups!$A$2:$A$14,0)),"") | K10: PT | L10: =IF(J10="n/a","n/a",IFERROR(IF(ABS(INDEX(Lookups!$H$2:$H$5,MATCH(J10,Lookups!$G$2:$G$5,0))-INDEX(Lookups!$H$2:$H$5,MATCH(K10,Lookups!$G$2:$G$5,0)))<=1,"Yes","No"),"Check")) | M10: 52502.57 | N10: Yes | O10: 2 | Q10: =IF(N10<>"Yes","n/a",IF(OR(AND(O10<>"",O10>$W$1),P10="Y"),"Yes",IF(O10<>"","No","Pending"))) | S10: Cody Nichols | T10: State | U10: Agenda & Video, Public Records Request | X10: C | Y10: 42 | Z10: 0.75 | AA10: 0.552 | AB10: 4 | AC10: Maintain | AD10: 0.3 | AE10: reported
A11: Oregon Teacher Standards and Practices Commission | B11: Oregon | C11: OR | D11: State | E11: Todd Bowers | F11: Paige Wendle | G11: Paige Wendle | H11: =IF(F11="(not in WIP)","New to Enterprise",IF(F11=G11,"No","Yes")) | I11: =IFERROR(INDEX(Lookups!$B$2:$B$14,MATCH(G11,Lookups!$A$2:$A$14,0)),"Not found") | J11: =IFERROR(INDEX(Lookups!$E$2:$E$14,MATCH(G11,Lookups!$A$2:$A$14,0)),"") | K11: PT | L11: =IF(J11="n/a","n/a",IFERROR(IF(ABS(INDEX(Lookups!$H$2:$H$5,MATCH(J11,Lookups!$G$2:$G$5,0))-INDEX(Lookups!$H$2:$H$5,MATCH(K11,Lookups!$G$2:$G$5,0)))<=1,"Yes","No"),"Check")) | M11: 42446.25 | N11: Yes | O11: 4 | Q11: =IF(N11<>"Yes","n/a",IF(OR(AND(O11<>"",O11>$W$1),P11="Y"),"Yes",IF(O11<>"","No","Pending"))) | S11: Kristen Murphy | T11: State | U11: Email & SMS, Engagement & Sentiment, Recurring Services, govXCloud | X11: C | Y11: 42 | Z11: 0.5 | AA11: 0.452 | AB11: 4 | AC11: Maintain | AD11: 0.3 | AE11: reported
A12: Washington Department of Transportation | B12: Washington Department of Enterprise Services | C12: WA | D12: State | E12: Todd Bowers | F12: Paige Wendle | G12: Paige Wendle | H12: =IF(F12="(not in WIP)","New to Enterprise",IF(F12=G12,"No","Yes")) | I12: =IFERROR(INDEX(Lookups!$B$2:$B$14,MATCH(G12,Lookups!$A$2:$A$14,0)),"Not found") | J12: =IFERROR(INDEX(Lookups!$E$2:$E$14,MATCH(G12,Lookups!$A$2:$A$14,0)),"") | K12: PT | L12: =IF(J12="n/a","n/a",IFERROR(IF(ABS(INDEX(Lookups!$H$2:$H$5,MATCH(J12,Lookups!$G$2:$G$5,0))-INDEX(Lookups!$H$2:$H$5,MATCH(K12,Lookups!$G$2:$G$5,0)))<=1,"Yes","No"),"Check")) | M12: 301828.73 | N12: Yes | O12: 4 | Q12: =IF(N12<>"Yes","n/a",IF(OR(AND(O12<>"",O12>$W$1),P12="Y"),"Yes",IF(O12<>"","No","Pending"))) | S12: Paige Wendle | T12: State | U12: Email & SMS, Engagement & Sentiment, Public Records Request, Recurring Services | X12: D | Y12: 33.6 | Z12: 0.5 | AA12: 0.4016 | AB12: 3 | AC12: Defend | AD12: 0.5 | AE12: reported
A13: Washington State Department of Health | B13: Washington Department of Enterprise Services | C13: WA | D13: State | E13: Todd Bowers | F13: Paige Wendle | G13: Paige Wendle | H13: =IF(F13="(not in WIP)","New to Enterprise",IF(F13=G13,"No","Yes")) | I13: =IFERROR(INDEX(Lookups!$B$2:$B$14,MATCH(G13,Lookups!$A$2:$A$14,0)),"Not found") | J13: =IFERROR(INDEX(Lookups!$E$2:$E$14,MATCH(G13,Lookups!$A$2:$A$14,0)),"") | K13: PT | L13: =IF(J13="n/a","n/a",IFERROR(IF(ABS(INDEX(Lookups!$H$2:$H$5,MATCH(J13,Lookups!$G$2:$G$5,0))-INDEX(Lookups!$H$2:$H$5,MATCH(K13,Lookups!$G$2:$G$5,0)))<=1,"Yes","No"),"Check")) | M13: 296031.42 | N13: Yes | O13: 2 | Q13: =IF(N13<>"Yes","n/a",IF(OR(AND(O13<>"",O13>$W$1),P13="Y"),"Yes",IF(O13<>"","No","Pending"))) | S13: Paige Wendle | T13: State | U13: Email & SMS, Public Records Request | X13: D | Y13: 33.6 | Z13: 0.75 | AA13: 0.5016 | AB13: 3 | AC13: Defend | AD13: 0.5 | AE13: reported
